<?xml version="1.0" encoding="utf-8"?>
<!-- This URDF was automatically created by SolidWorks to URDF Exporter! Originally created by Stephen Brawner (brawner@gmail.com) 
     Commit Version: 1.6.0-4-g7f85cfe  Build Version: 1.6.7995.38578
     For more information, please see http://wiki.ros.org/sw_urdf_exporter -->
<robot
  name="tangba">
    
  <gazebo>
    <plugin name="gazebo_ros_control" filename="libhunter_bipedal_hw_sim.so">
      <robotNamespace>/</robotNamespace>
      <robotParam>legged_robot_description</robotParam>
      <robotSimType>legged_gazebo/LeggedHWSim</robotSimType>
    </plugin>
  </gazebo>

  <gazebo>
    <plugin filename="libgazebo_ros_p3d.so" name="p3d_base_controller">
      <alwaysOn>true</alwaysOn>
      <updateRate>500.0</updateRate>
      <bodyName>base_link</bodyName>
      <topicName>ground_truth/state</topicName>
      <gaussianNoise>0</gaussianNoise>
      <frameName>world</frameName>
      <xyzOffsets>0 0 0</xyzOffsets>
      <rpyOffsets>0 0 0</rpyOffsets>
    </plugin>
  </gazebo>

  <link
    name="base_link">
    <inertial>
      <origin
        xyz="-0.0381325 -0.0043577 0.1372842"
        rpy="0 0 0" />
      <mass
        value="3.71439" />
      <inertia
        ixx="0.0693054"
        ixy="-0.0012640"
        ixz="0.0028288"
        iyy="0.1060973"
        iyz="0.0053874"
        izz="0.0974062" />
    </inertial>
    <visual>
      <origin
        xyz="0 0 0"
        rpy="0 0 0" />
      <geometry>
        <mesh
          filename="package://legged_hunter_description/tangba_meshes/base_link.STL" />
      </geometry>
      <material
        name="">
        <color
          rgba="1 1 1 1" />
      </material>
    </visual>
    <collision>
      <origin
        xyz="0 0 0"
        rpy="0 0 0" />
      <geometry>
        <box size="0.001 0.001 0.001" /><!--宽 长 高!-->
      </geometry>
    </collision>
  </link>
  <!-- Imu is fixed to the base link -->
  <joint name="imu_joint" type="fixed">
    <origin rpy="0. 0. 0." xyz="0. 0. 0"/>
    <parent link="base_link"/>
    <child link="imu_link"/>
  </joint>
  <!-- Imu link -->
  <link name="imu_link">
    <inertial>
      <mass value="0.01"/>
      <origin rpy="0 0 0" xyz="0 0 0"/>
      <inertia ixx="0.000001" ixy="0" ixz="0" iyy="0.000001" iyz="0" izz="0.000001"/>
    </inertial>
    <visual>
      <origin rpy="0 0 0" xyz="0 0 0"/>
      <geometry>
        <box size="0.015 0.015 0.004"/>
      </geometry>
    </visual>
    <material name="orange">
      <color rgba="255 108 10 255"/>
    </material>
  </link>
  <gazebo reference="imu_joint">
    <disableFixedJointLumping>true</disableFixedJointLumping>
  </gazebo>

  <link
    name="leg_l1_link">
    <inertial>
      <origin
        xyz="0.0304529 -0.0000146 -0.0635827"
        rpy="0 0 0" />
      <mass
        value="1.2581230" />
      <inertia
        ixx="0.0011909"
        ixy="-0.0000006"
        ixz="0.0002906"
        iyy="0.0011775"
        iyz="-0.0000001"
        izz="0.0005895" />
    </inertial>
    <visual>
      <origin
        xyz="0 0 0"
        rpy="0 0 0" />
      <geometry>
        <mesh
          filename="package://legged_hunter_description/tangba_meshes/link_left_hip_yaw.STL" />
      </geometry>
      <material
        name="">
        <color
          rgba="1 1 1 1" />
      </material>
    </visual>
    <collision>
      <origin
        xyz="0 0 0"
        rpy="0 0 0" />
      <geometry>
        <box size="0.001 0.001 0.001" /><!--宽 长 高!-->
      </geometry>
    </collision>
  </link>
  <joint
    name="leg_l1_joint"
    type="revolute">
    <origin
      xyz="0.0200750000000063 0.0680000000000003 0.138"
      rpy="0 0 0" />
    <parent
      link="base_link" />
    <child
      link="leg_l1_link" />
    <axis
      xyz="0 0 1" />
    <limit
      lower="-0.34906"
      upper="0.34906"
      effort="12"
      velocity="14" />
  </joint>
  <link
    name="leg_l2_link">
    <inertial>
      <origin
        xyz="0.0410651 -0.0001061 0.0182024"
        rpy="0 0 0" />
      <mass
        value="0.4307105" />
      <inertia
        ixx="0.0001837"
        ixy="0.0000017"
        ixz="-0.0000761"
        iyy="0.0005959"
        iyz="0.0000002"
        izz="0.0006400" />
    </inertial>
    <visual>
      <origin
        xyz="0 0 0"
        rpy="0 0 0" />
      <geometry>
        <mesh
          filename="package://legged_hunter_description/tangba_meshes/link_left_hip_roll.STL" />
      </geometry>
      <material
        name="">
        <color
          rgba="0.898039215686275 0.917647058823529 0.929411764705882 1" />
      </material>
    </visual>
    <collision>
      <origin
        xyz="0 0 0"
        rpy="0 0 0" />
      <geometry>
          <box size="0.001 0.001 0.001" /><!--宽 长 高!-->
      </geometry>
    </collision>
  </link>
  <joint
    name="leg_l2_joint"
    type="revolute">
    <origin
      xyz="0.0225 0 -0.0715"
      rpy="-1.5707963267949 0 1.57079632679489" />
    <parent
      link="leg_l1_link" />
    <child
      link="leg_l2_link" />
    <axis
      xyz="-0.0355014772726285 0 0.999369623868697" />
    <limit
      lower="-0.1745"
      upper="0.34906"
      effort="12"
      velocity="14" />
  </joint>
  <link
    name="leg_l3_link">
    <inertial>
      <origin
        xyz="-0.0689138  -0.0570379 -0.0228633"
        rpy="0 0 0" />
      <mass
        value="2.9774665" />
      <inertia
        ixx="0.0106822"
        ixy="-0.0086380"
        ixz="-0.0010399"
        iyy="0.0133553"
        iyz="-0.0008543"
        izz="0.0224789" />
    </inertial>
    <visual>
      <origin
        xyz="0 0 0"
        rpy="0 0 0" />
      <geometry>
        <mesh
          filename="package://legged_hunter_description/tangba_meshes/link_left_hip_pitch.STL" />
      </geometry>
      <material
        name="">
        <color
          rgba="1 1 1 1" />
      </material>
    </visual>
    <collision>
      <origin
        xyz="0 0 -0.03"
        rpy="0 0 0" />
      <geometry>
        <box size="0.12 0.1 0.06" /> <!--宽 长 高!-->
      </geometry>
    </collision>
  </link>
  <joint
    name="leg_l3_joint"
    type="revolute">
    <origin
      xyz="0.0849999999999993 0 0.0224999999279662"
      rpy="3.14159265358979 1.5707963267949 0" />
    <parent
      link="leg_l2_link" />
    <child
      link="leg_l3_link" />
    <axis
      xyz="0.0355014772726165 0 0.999369623868697" />
    <limit
      lower="-0.6981"
      upper="1.8"
      effort="12"
      velocity="14" />
  </joint>
  <link
    name="leg_l4_link">
    <inertial>
      <origin
        xyz=" 0.0796166 -0.0850826  -0.0175707"
        rpy="0 0 0" />
      <mass
        value="1.5242262" />
      <inertia
        ixx="0.0040232"
        ixy="0.0026807"
        ixz="0.0007623"
        iyy="0.0036656"
        iyz="-0.0008197"
        izz="0.0067465" />
    </inertial>
    <visual>
      <origin
        xyz="0 0 0"
        rpy="0 0 0" />
      <geometry>
        <mesh
          filename="package://legged_hunter_description/tangba_meshes/link_left_knee.STL" />
      </geometry>
      <material
        name="">
        <color
          rgba="1 1 1 1" />
      </material>
    </visual>
    <collision>
      <origin
        xyz="0 -0.0 -0.02"
        rpy="0 0 0" />
      <geometry>
        <box size="0.12 0.1 0.06" /> <!-- 膝关节部件 -->
      </geometry>
    </collision>
  </link>
  <joint
    name="leg_l4_joint"
    type="revolute">
    <origin
      xyz="-0.119085999406409 -0.10231092202195 -0.00450000000000123"
      rpy="0 0 0" />
    <parent
      link="leg_l3_link" />
    <child
      link="leg_l4_link" />
    <axis
      xyz="0 0 -1" />
    <limit
      lower="-0.6806784082777885"
      upper="1.5707963267948966"
      effort="30"
      velocity="14" />
  </joint>
  <link
    name="leg_l_f2_link">
  </link>
  <joint
    name="leg_l5_fixed_2"
    type="fixed">
    <origin
      xyz="-0.094 -0.031 -0.11"
      rpy="0 0 0" />
    <parent
      link="leg_l5_link" />
    <child
      link="leg_l_f2_link" />
  </joint>
  <link
    name="leg_l_f1_link">
  </link>
  <joint
    name="leg_l5_fixed_1"
    type="fixed">
    <origin
      xyz="0.1515 -0.031 -0.11"
      rpy="0 0 0" />
    <parent
      link="leg_l5_link" />
    <child
      link="leg_l_f1_link" />
  </joint>
  <link
    name="leg_l5_link">
    <inertial>
      <origin
        xyz="0.0242470 -0.0130185 -0.0732293"
        rpy="0 0 0" />
      <mass
        value="1.3694143" />
      <inertia
        ixx="0.0033166"
        ixy="0.0001626"
        ixz="0.0005165"
        iyy="0.0062601"
        iyz="-0.0006330"
        izz="0.0054879" />
    </inertial>
    <visual>
      <origin
        xyz="0 0 0"
        rpy="0 0 0" />
      <geometry>
        <mesh
          filename="package://legged_hunter_description/tangba_meshes/link_left_ankle.STL" />
      </geometry>
      <material
        name="">
        <color
          rgba="0.792156862745098 0.819607843137255 0.933333333333333 1" />
      </material>
    </visual>
    <collision>
      <origin
        xyz="0.02 -0.03 -0.03"
        rpy="0 0 0" />
      <geometry>
        <box size="0.23 0.08 0.15" /> <!-- 踝关节部件 -->
      </geometry>
    </collision>
  </link>
  <joint
    name="leg_l5_joint"
    type="revolute">
    <origin
      xyz="0.101882292521187 -0.109129160590203 -0.0445000000000359"
      rpy="-1.5707 0 0" />
    <parent
      link="leg_l4_link" />
    <child
      link="leg_l5_link" />
    <axis
      xyz="0 -1 0" />
    <limit
      lower="-0.5061454830783556"
      upper="1.064650843716541"
      effort="12"
      velocity="14" />
  </joint>
<!-- gazebo left_leg-->
<gazebo reference="leg_l1_link">
    <mu1>0.6</mu1>
    <mu2>0.6</mu2>
    <self_collide>1</self_collide>
  </gazebo>
  <gazebo reference="leg_l2_link">
    <mu1>0.6</mu1>
    <mu2>0.6</mu2>
    <self_collide>1</self_collide>
  </gazebo>
  <gazebo reference="leg_l3_link">
    <mu1>0.6</mu1>
    <mu2>0.6</mu2>
    <self_collide>1</self_collide>
  </gazebo>
  <gazebo reference="leg_l4_link">
    <mu1>0.6</mu1>
    <mu2>0.6</mu2>
    <self_collide>1</self_collide>
  </gazebo>
  <gazebo reference="leg_l5_link">
    <mu1>1.5</mu1>
    <mu2>1.5</mu2>
    <self_collide>1</self_collide>
    <kp value="1000000.0"/>
    <kd value="100.0"/>
    <maxVel>1.0</maxVel>
    <minDepth>0.00</minDepth>
  </gazebo>
  <gazebo reference="leg_l_f1_link">
    <mu1>1.5</mu1>
    <mu2>1.5</mu2>
    <self_collide>1</self_collide>
    <kp value="1000000.0"/>
    <kd value="100.0"/>
    <maxVel>1.0</maxVel>
    <minDepth>0.00</minDepth>
  </gazebo>
  <gazebo reference="leg_l_f2_link">
    <mu1>1.5</mu1>
    <mu2>1.5</mu2>
    <self_collide>1</self_collide>
    <kp value="1000000.0"/>
    <kd value="100.0"/>
    <maxVel>1.0</maxVel>
    <minDepth>0.00</minDepth>
  </gazebo>

  <transmission name="leg_l1_tran">
    <type>transmission_interface/SimpleTransmission</type>
    <joint name="leg_l1_joint">
      <hardwareInterface>hardware_interface/EffortJointInterface</hardwareInterface>
    </joint>
    <actuator name="leg_l1_motor">
      <hardwareInterface>hardware_interface/EffortJointInterface</hardwareInterface>
      <mechanicalReduction>1</mechanicalReduction>
    <maxVelocity>1.484</maxVelocity><!-- 85rpm -->
	  <maxEffort>36.0</maxEffort><!-- 36Nm -->
    </actuator>
  </transmission>

  <transmission name="leg_l2_tran">
    <type>transmission_interface/SimpleTransmission</type>
    <joint name="leg_l2_joint">
      <hardwareInterface>hardware_interface/EffortJointInterface</hardwareInterface>
    </joint>
    <actuator name="leg_l2_motor">
      <hardwareInterface>hardware_interface/EffortJointInterface</hardwareInterface>
      <mechanicalReduction>1</mechanicalReduction>
    <maxVelocity>2.6545</maxVelocity><!-- 160rpm -->
	  <maxEffort>94.0</maxEffort><!-- 94Nm -->
    </actuator>
  </transmission>

  <transmission name="leg_l3_tran">
    <type>transmission_interface/SimpleTransmission</type>
    <joint name="leg_l3_joint">
      <hardwareInterface>hardware_interface/EffortJointInterface</hardwareInterface>
    </joint>
    <actuator name="leg_l3_motor">
      <hardwareInterface>hardware_interface/EffortJointInterface</hardwareInterface>
      <mechanicalReduction>1</mechanicalReduction>
    <maxVelocity>2.6545</maxVelocity><!-- 160rpm -->
	  <maxEffort>94.0</maxEffort><!-- 94Nm -->
    </actuator>
  </transmission>

  <transmission name="leg_l4_tran">
    <type>transmission_interface/SimpleTransmission</type>
    <joint name="leg_l4_joint">
      <hardwareInterface>hardware_interface/EffortJointInterface</hardwareInterface>
    </joint>
    <actuator name="leg_l4_motor">
      <hardwareInterface>hardware_interface/EffortJointInterface</hardwareInterface>
      <mechanicalReduction>1</mechanicalReduction>
    <maxVelocity>1.484</maxVelocity><!-- 85rpm -->
	<maxEffort>36.0</maxEffort><!-- 36Nm -->
    </actuator>
  </transmission>

  <transmission name="leg_l5_tran">
    <type>transmission_interface/SimpleTransmission</type>
    <joint name="leg_l5_joint">
      <hardwareInterface>hardware_interface/EffortJointInterface</hardwareInterface>
    </joint>
    <actuator name="leg_l5_motor">
      <hardwareInterface>hardware_interface/EffortJointInterface</hardwareInterface>
      <mechanicalReduction>1</mechanicalReduction>
    </actuator>
  </transmission>


  <link
    name="leg_r1_link">
    <inertial>
      <origin
        xyz="0.0304529 -0.0000146 -0.0635827"
        rpy="0 0 0" />
      <mass
        value="1.2581230" />
      <inertia
        ixx="0.0011909"
        ixy="-0.0000006"
        ixz="0.0002906"
        iyy="0.0011775"
        iyz="-0.0000001"
        izz="0.0005895" />
    </inertial>
    <visual>
      <origin
        xyz="0 0 0"
        rpy="0 0 0" />
      <geometry>
        <mesh
          filename="package://legged_hunter_description/tangba_meshes/link_right_hip_yaw.STL" />
      </geometry>
      <material
        name="">
        <color
          rgba="1 1 1 1" />
      </material>
    </visual>
    <collision>
      <origin
        xyz="0 0 0"
        rpy="0 0 0" />
      <geometry>
          <box size="0.001 0.001 0.001" /><!--宽 长 高!-->
      </geometry>
    </collision>
  </link>
  <joint
    name="leg_r1_joint"
    type="revolute">
    <origin
      xyz="0.0200750000000058 -0.0679999999999992 0.138"
      rpy="0 0 0" />
    <parent
      link="base_link" />
    <child
      link="leg_r1_link" />
    <axis
      xyz="0 0 1" />
    <limit
      lower="-0.34906"
      upper="0.34906"
      effort="12"
      velocity="14" />
  </joint>
  <link
    name="leg_r2_link">
    <inertial>
      <origin
        xyz="-0.0410699 -0.0001072 0.0182781"
        rpy="0 0 0" />
      <mass
        value="0.4307105" />
      <inertia
        ixx="0.0001829"
        ixy="-0.0000018"
        ixz="0.0000747"
        iyy="0.0005949"
        iyz="0.0000002"
        izz="0.0006399" />
    </inertial>
    <visual>
      <origin
        xyz="0 0 0"
        rpy="0 0 0" />
      <geometry>
        <mesh
          filename="package://legged_hunter_description/tangba_meshes/link_right_hip_roll.STL" />
      </geometry>
      <material
        name="">
        <color
          rgba="1 1 1 1" />
      </material>
    </visual>
    <collision>
      <origin
        xyz="0 0 0"
        rpy="0 0 0" />
      <geometry>
          <box size="0.001 0.001 0.001" /><!--宽 长 高!-->
      </geometry>
    </collision>
  </link>
  <joint
    name="leg_r2_joint"
    type="revolute">
    <origin
      xyz="0.0224999999999977 0 -0.0714999999999994"
      rpy="-1.57079632679488 0 1.5707963267949" />
    <parent
      link="leg_r1_link" />
    <child
      link="leg_r2_link" />
    <axis
      xyz="0 0 -1" />
    <limit
      lower="-0.17453"
      upper="0.34906"
      effort="12"
      velocity="14" />
  </joint>
  <link
    name="leg_r3_link">
    <inertial>
      <origin
        xyz="-0.0658430 0.0604391 -0.0228601"
        rpy="0 0 0" />
      <mass
        value="2.9802188" />
      <inertia
        ixx="0.0116178"
        ixy="0.0087373"
        ixz="-0.0009989"
        iyy=" 0.0124470"
        iyz=" 0.0008994"
        izz=" 0.0225059" />
    </inertial>
    <visual>
      <origin
        xyz="0 0 0"
        rpy="0 0 0" />
      <geometry>
        <mesh
          filename="package://legged_hunter_description/tangba_meshes/link_right_hip_pitch.STL" />
      </geometry>
      <material
        name="">
        <color
          rgba="1 1 1 1" />
      </material>
    </visual>
    <collision>
      <origin
        xyz="0 0 -0.03"
        rpy="0 0 0" />
      <geometry>
        <box size="0.12 0.1 0.06" /><!--宽 长 高!-->
      </geometry>
    </collision>
  </link>
  <joint
    name="leg_r3_joint"
    type="revolute">
    <origin
      xyz="-0.0849999999999561 0 0.0224999999468524"
      rpy="0 1.5707963267949 0" />
    <parent
      link="leg_r2_link" />
    <child
      link="leg_r3_link" />
    <axis
      xyz="0 0 -1" />
    <limit
      lower="-0.698131"
      upper="1.8"
      effort="12"
      velocity="14" />
  </joint>
  <link
    name="leg_r4_link">
    <inertial>
      <origin
        xyz="0.0795575 -0.0850556 0.0175435"
        rpy="0 0 0" />
      <mass
        value="1.5250154" />
      <inertia
        ixx="0.0040319"
        ixy="0.0026859"
        ixz="-0.0007641"
        iyy="0.0036710"
        iyz="0.0008245"
        izz="0.0067574" />
    </inertial>
    <visual>
      <origin
        xyz="0 0 0"
        rpy="0 0 0" />
      <geometry>
        <mesh
          filename="package://legged_hunter_description/tangba_meshes/link_right_knee.STL" />
      </geometry>
      <material
        name="">
        <color
          rgba="1 1 1 1" />
      </material>
    </visual>
    <collision>
      <origin
        xyz="0.0 0.0 0.02"
        rpy="0 0 0" />
      <geometry>
        <box size="0.12 0.1 0.06" /> <!-- 膝关节部件 -->
      </geometry>
    </collision>
  </link>
  <joint
    name="leg_r4_joint"
    type="revolute">
    <origin
      xyz="-0.114760457317049 0.107140270037781 -0.00450000000003428"
      rpy="3.14159265358979 0 0" />
    <parent
      link="leg_r3_link" />
    <child
      link="leg_r4_link" />
    <axis
      xyz="0 0 1" />
    <limit
      lower="-1.5707963"
      upper="0.680678"
      effort="30"
      velocity="14" />
  </joint>
  <link
    name="leg_r_f1_link">
  </link>
  <joint
    name="leg_r5_fixed_1"
    type="fixed">
    <origin
      xyz="0.1515 0.031 -0.11"
      rpy="0 0 0" />
    <parent
      link="leg_r5_link" />
    <child
      link="leg_r_f1_link" />
  </joint>
  <link
    name="leg_r_f2_link">
  </link>
  <joint
    name="leg_r5_fixed_2"
    type="fixed">
    <origin
      xyz="-0.094 0.031 -0.11"
      rpy="0 0 0" />
    <parent
      link="leg_r5_link" />
    <child
      link="leg_r_f2_link" />
  </joint>
  <link
    name="leg_r5_link">
    <inertial>
      <origin
        xyz="0.0243158 0.0130219 -0.0732098"
        rpy="0 0 0" />
      <mass
        value="1.3695979" />
      <inertia
        ixx="0.0033159"
        ixy="-0.0001637"
        ixz="0.0005149"
        iyy="0.0062627"
        iyz="0.0006329"
        izz="0.0054913" />
    </inertial>
    <visual>
      <origin
        xyz="0 0 0"
        rpy="0 0 0" />
      <geometry>
        <mesh
          filename="package://legged_hunter_description/tangba_meshes/link_right_ankle.STL" />
      </geometry>
      <material
        name="">
        <color
          rgba="1 1 1 1" />
      </material>
    </visual>
    <collision>
      <origin
        xyz="0.02 0.03 -0.03"
        rpy="0 0 0" />
      <geometry>
        <box size="0.23 0.08 0.15" /> <!-- 踝关节部件 -->
      </geometry>
    </collision>
  </link>
  <joint
    name="leg_r5_joint"
    type="revolute">
    <origin
      xyz="0.10199 -0.10903 0.0445"
      rpy="-1.5707 0 0" />
    <parent
      link="leg_r4_link" />
    <child
      link="leg_r5_link" />
    <axis
      xyz="0 1 0" />
    <limit
      lower="-1.0646"
      upper="0.50614"
      effort="12"
      velocity="14" />
  </joint>
<gazebo reference="leg_r1_link">
    <mu1>0.6</mu1>
    <mu2>0.6</mu2>
    <self_collide>1</self_collide>
  </gazebo>
  <gazebo reference="leg_r2_link">
    <mu1>0.6</mu1>
    <mu2>0.6</mu2>
    <self_collide>1</self_collide>
  </gazebo>
  <gazebo reference="leg_r3_link">
    <mu1>0.6</mu1>
    <mu2>0.6</mu2>
    <self_collide>1</self_collide>
  </gazebo>
  <gazebo reference="leg_r4_link">
    <mu1>0.6</mu1>
    <mu2>0.6</mu2>
    <self_collide>1</self_collide>
  </gazebo>
  <gazebo reference="leg_r5_link">
    <mu1>1.5</mu1>
    <mu2>1.5</mu2>
    <self_collide>1</self_collide>
    <kp value="1000000.0"/>
    <kd value="100.0"/>
    <maxVel>1.0</maxVel>
    <minDepth>0.00</minDepth>
  </gazebo>
  <gazebo reference="leg_r_f1_link">
    <mu1>1.5</mu1>
    <mu2>1.5</mu2>
    <self_collide>1</self_collide>
    <kp value="1000000.0"/>
    <kd value="100.0"/>
    <maxVel>1.0</maxVel>
    <minDepth>0.00</minDepth>
  </gazebo>
  <gazebo reference="leg_r_f2_link">
    <mu1>1.5</mu1>
    <mu2>1.5</mu2>
    <self_collide>1</self_collide>
    <kp value="1000000.0"/>
    <kd value="100.0"/>
    <maxVel>1.0</maxVel>
    <minDepth>0.00</minDepth>
  </gazebo>

  <transmission name="leg_r1_tran">
    <type>transmission_interface/SimpleTransmission</type>
    <joint name="leg_r1_joint">
      <hardwareInterface>hardware_interface/EffortJointInterface</hardwareInterface>
    </joint>
    <actuator name="leg_r1_motor">
      <hardwareInterface>hardware_interface/EffortJointInterface</hardwareInterface>
      <mechanicalReduction>1</mechanicalReduction>
      	  <maxVelocity>1.484</maxVelocity><!-- 85rpm -->
	<maxEffort>36.0</maxEffort><!-- 36Nm -->
    </actuator>
  </transmission>

  <transmission name="leg_r2_tran">
    <type>transmission_interface/SimpleTransmission</type>
    <joint name="leg_r2_joint">
      <hardwareInterface>hardware_interface/EffortJointInterface</hardwareInterface>
    </joint>
    <actuator name="leg_r2_motor">
      <hardwareInterface>hardware_interface/EffortJointInterface</hardwareInterface>
      <mechanicalReduction>1</mechanicalReduction>
      	  <maxVelocity>2.6545</maxVelocity><!-- 160rpm -->
	  <maxEffort>94.0</maxEffort><!-- 94Nm -->
    </actuator>
  </transmission>

  <transmission name="leg_r3_tran">
    <type>transmission_interface/SimpleTransmission</type>
    <joint name="leg_r3_joint">
      <hardwareInterface>hardware_interface/EffortJointInterface</hardwareInterface>
    </joint>
    <actuator name="leg_r3_motor">
      <hardwareInterface>hardware_interface/EffortJointInterface</hardwareInterface>
      <mechanicalReduction>1</mechanicalReduction>
      	  <maxVelocity>2.6545</maxVelocity><!-- 160rpm -->
	  <maxEffort>94.0</maxEffort><!-- 94Nm -->
    </actuator>
  </transmission>

  <transmission name="leg_r4_tran">
    <type>transmission_interface/SimpleTransmission</type>
    <joint name="leg_r4_joint">
      <hardwareInterface>hardware_interface/EffortJointInterface</hardwareInterface>
    </joint>
    <actuator name="leg_r4_motor">
      <hardwareInterface>hardware_interface/EffortJointInterface</hardwareInterface>
      <mechanicalReduction>1</mechanicalReduction>
      	  <maxVelocity>1.484</maxVelocity><!-- 85rpm -->
	<maxEffort>36.0</maxEffort><!-- 36Nm -->
    </actuator>
  </transmission>

  <transmission name="leg_r5_tran">
    <type>transmission_interface/SimpleTransmission</type>
    <joint name="leg_r5_joint">
      <hardwareInterface>hardware_interface/EffortJointInterface</hardwareInterface>
    </joint>
    <actuator name="leg_r5_motor">
      <hardwareInterface>hardware_interface/EffortJointInterface</hardwareInterface>
      <mechanicalReduction>1</mechanicalReduction>
    </actuator>
  </transmission>

  <!-- <link
    name="link_neck_pitch">
    <inertial>
      <origin
        xyz="-0.0628997 0.0715822 -0.0077625"
        rpy="0 0 0" />
      <mass
        value="0.8994009" />
      <inertia
        ixx="0.0016865"
        ixy="0.0010580"
        ixz="-0.0003033"
        iyy="0.0015035"
        iyz="0.0003194"
        izz="0.0026739" />
    </inertial>
    <visual>
      <origin
        xyz="0 0 0"
        rpy="0 0 0" />
      <geometry>
        <mesh
          filename="package://legged_hunter_description/tangba_meshes/link_neck_pitch.STL" />
      </geometry>
      <material
        name="">
        <color
          rgba="1 1 1 1" />
      </material>
    </visual>
    <collision>
      <origin
        xyz="0 0 0"
        rpy="0 0 0" />
      <geometry>
        <mesh
          filename="package://legged_hunter_description/tangba_meshes/link_neck_pitch.STL" />
      </geometry>
    </collision>
  </link> -->
  <!-- <joint
    name="joint_neck_pitch"
    type="revolute">
    <origin
      xyz="0.12508 -0.0225 0.1675"
      rpy="1.5708 0 0" />
    <parent
      link="base_link" />
    <child
      link="link_neck_pitch" />
    <axis
      xyz="0 0 1" />
    <limit
      lower="-0.8"
      upper="0.17"
      effort="30"
      velocity="14" />
  </joint>
  <link
    name="link_head_pitch">
    <inertial>
      <origin
        xyz="0.0001020 0.0616982  -0.0172628"
        rpy="0 0 0" />
      <mass
        value="0.5844865" />
      <inertia
        ixx="0.0006356"
        ixy="-0.0000036"
        ixz="-0.0000038"
        iyy="0.0002990"
        iyz="0.0000243"
        izz="0.0004868" />
    </inertial>
    <visual>
      <origin
        xyz="0 0 0"
        rpy="0 0 0" />
      <geometry>
        <mesh
          filename="package://legged_hunter_description/tangba_meshes/link_head_pitch.STL" />
      </geometry>
      <material
        name="">
        <color
          rgba="1 1 1 1" />
      </material>
    </visual>
    <collision>
      <origin
        xyz="0 0 0"
        rpy="0 0 0" />
      <geometry>
        <mesh
          filename="package://legged_hunter_description/tangba_meshes/link_head_pitch.STL" />
      </geometry>
    </collision>
  </link>
  <joint
    name="joint_head_pitch"
    type="revolute">
    <origin
      xyz="-0.083976 0.093265 0.0021976"
      rpy="0 0 0" />
    <parent
      link="link_neck_pitch" />
    <child
      link="link_head_pitch" />
    <axis
      xyz="0 0 1" />
    <limit
      lower="-0.1"
      upper="1.57"
      effort="30"
      velocity="14" />
  </joint>
  <link
    name="link_head_yaw">
    <inertial>
      <origin
        xyz="0.0022326 -0.0000120 0.0411668"
        rpy="0 0 0" />
      <mass
        value="0.5449386" />
      <inertia
        ixx="0.0002460"
        ixy="0.0000002"
        ixz="-0.0000221"
        iyy="0.0002121"
        iyz="0.0000004"
        izz="0.0001209" />
    </inertial>
    <visual>
      <origin
        xyz="0 0 0"
        rpy="0 0 0" />
      <geometry>
        <mesh
          filename="package://legged_hunter_description/tangba_meshes/link_head_yaw.STL" />
      </geometry>
      <material
        name="">
        <color
          rgba="1 1 1 1" />
      </material>
    </visual>
    <collision>
      <origin
        xyz="0 0 0"
        rpy="0 0 0" />
      <geometry>
        <mesh
          filename="package://legged_hunter_description/tangba_meshes/link_head_yaw.STL" />
      </geometry>
    </collision>
  </link>
  <joint
    name="joint_head_yaw"
    type="revolute">
    <origin
      xyz="0 0.092 -0.0175"
      rpy="-1.5708 3.1415926 0" />
    <parent
      link="link_head_pitch" />
    <child
      link="link_head_yaw" />
    <axis
      xyz="0 0 1" />
    <limit
      lower="-1.2"
      upper="1.2"
      effort="30"
      velocity="14" />
  </joint>
  <link
    name="link_head_roll">
    <inertial>
      <origin
        xyz="-0.0029343 0.0022616  -0.0318039"
        rpy="0 0 0" />
      <mass
        value="4.3659297" />
      <inertia
        ixx="0.1261924"
        ixy="-0.0006052"
        ixz="0.0004602"
        iyy="0.0435845"
        iyz="0.0003243"
        izz="0.1411790" />
    </inertial>
    <visual>
      <origin
        xyz="0 0 0"
        rpy="0 0 0" />
      <geometry>
        <mesh
          filename="package://legged_hunter_description/tangba_meshes/link_head_roll.STL" />
      </geometry>
      <material
        name="">
        <color
          rgba="1 1 1 1" />
      </material>
    </visual>
    <collision>
      <origin
        xyz="0 0 0"
        rpy="0 0 0" />
      <geometry>
        <mesh
          filename="package://legged_hunter_description/tangba_meshes/link_head_roll.STL" />
      </geometry>
    </collision>
  </link>
  <joint
    name="joint_head_roll"
    type="revolute">
    <origin
      xyz="0.018 0 0.047"
      rpy="3.1416 -1.5708 0" />
    <parent
      link="link_head_yaw" />
    <child
      link="link_head_roll" />
    <axis
      xyz="0 0 1" />
    <limit
      lower="-0.17"
      upper="0.17"
      effort="30"
      velocity="14" />
  </joint>
  <link
    name="link_left_ear">
    <inertial>
      <origin
        xyz="-0.0005001 0.0206344 0.0075149"
        rpy="0 0 0" />
      <mass
        value="0.0710962" />
      <inertia
        ixx="0.0001006"
        ixy="0.0000000"
        ixz="0.0000000"
        iyy="0.0001094"
        iyz="-0.0000053"
        izz="0.0000279" />
    </inertial>
    <visual>
      <origin
        xyz="0 0 0"
        rpy="0 0 0" />
      <geometry>
        <mesh
          filename="package://legged_hunter_description/tangba_meshes/link_left_ear.STL" />
      </geometry>
      <material
        name="">
        <color
          rgba="1 1 1 1" />
      </material>
    </visual>
    <collision>
      <origin
        xyz="0 0 0"
        rpy="0 0 0" />
      <geometry>
        <mesh
          filename="package://legged_hunter_description/tangba_meshes/link_left_ear.STL" />
      </geometry>
    </collision>
  </link>
  <joint
    name="joint_left_ear"
    type="revolute">
    <origin
      xyz="0.05 0.2405 0.0159"
      rpy="3.1416 1.5708 3.1416" />
    <parent
      link="link_head_roll" />
    <child
      link="link_left_ear" />
    <axis
      xyz="0 -1 0" />
    <limit
      lower="0"
      upper="0"
      effort="0"
      velocity="0" />
  </joint>
  <link
    name="link_right_ear">
    <inertial>
      <origin
        xyz="-0.0005000 -0.0206344 0.0075149"
        rpy="0 0 0" />
      <mass
        value="0.0710962" />
      <inertia
        ixx="0.0001006"
        ixy="0.0000000"
        ixz="0.0000000"
        iyy="0.0001094"
        iyz="0.0000053"
        izz="0.0000279" />
    </inertial>
    <visual>
      <origin
        xyz="0 0 0"
        rpy="0 0 0" />
      <geometry>
        <mesh
          filename="package://legged_hunter_description/tangba_meshes/link_right_ear.STL" />
      </geometry>
      <material
        name="">
        <color
          rgba="1 1 1 1" />
      </material>
    </visual>
    <collision>
      <origin
        xyz="0 0 0"
        rpy="0 0 0" />
      <geometry>
        <mesh
          filename="package://legged_hunter_description/tangba_meshes/link_right_ear.STL" />
      </geometry>
    </collision>
  </link>
  <joint
    name="joint_right_ear"
    type="revolute">
    <origin
      xyz="0.05 -0.2405 0.0159"
      rpy="3.1416 1.5708 3.1416" />
    <parent
      link="link_head_roll" />
    <child
      link="link_right_ear" />
    <axis
      xyz="0 1 0" />
    <limit
      lower="0"
      upper="0"
      effort="0"
      velocity="0" />
  </joint> -->
</robot>
